Workbook

Sheet Main (Original)
A1: kata | B1: arti | C1: ipa | D1: type | E1: cerf | F1: top | G1: Copy Prompt
A2: new | B2: baru | C2: /nu/ | D2: ADJ, ADV | E2: A1 | F2: 27 | G2: =SUBSTITUTE(SUBSTITUTE(SUBSTITUTE(ai!$A$2, "[KATA]", A2), "[TYPE]", D2), "[CERF]", E2)
A3: more | B3: lagi | C3: /mɔr/ | D3: ADJ, ADV, NOUN | E3: A1 | F3: 28 | G3: =SUBSTITUTE(SUBSTITUTE(SUBSTITUTE(ai!$A$2, "[KATA]", A3), "[TYPE]", D3), "[CERF]", E3)
A4: home | B4: rumah | C4: /hoʊm/ | D4: ADJ, ADV, NOUN, VERB | E4: A1 | F4: 33 | G4: =SUBSTITUTE(SUBSTITUTE(SUBSTITUTE(ai!$A$2, "[KATA]", A4), "[TYPE]", D4), "[CERF]", E4)
A5: about | B5: tentang | C5: /əˈbaʊt/ | D5: ADJ, ADV | E5: A1 | F5: 36 | G5: =SUBSTITUTE(SUBSTITUTE(SUBSTITUTE(ai!$A$2, "[KATA]", A5), "[TYPE]", D5), "[CERF]", E5)
A6: page | B6: halaman | C6: /peɪʤ/ | D6: NOUN, VERB | E6: A1 | F6: 38 | G6: =SUBSTITUTE(SUBSTITUTE(SUBSTITUTE(ai!$A$2, "[KATA]", A6), "[TYPE]", D6), "[CERF]", E6)
A7: search | B7: mencari | C7: /sərʧ/ | D7: NOUN, VERB | E7: B1 | F7: 41 | G7: =SUBSTITUTE(SUBSTITUTE(SUBSTITUTE(ai!$A$2, "[KATA]", A7), "[TYPE]", D7), "[CERF]", E7)
A8: free | B8: bebas | C8: /fri/ | D8: ADJ, ADV, NOUN, VERB | E8: B2 | F8: 42 | G8: =SUBSTITUTE(SUBSTITUTE(SUBSTITUTE(ai!$A$2, "[KATA]", A8), "[TYPE]", D8), "[CERF]", E8)
A9: one | B9: satu | C9: /wən/ | D9: ADJ, NOUN | E9: A2 | F9: 45 | G9: =SUBSTITUTE(SUBSTITUTE(SUBSTITUTE(ai!$A$2, "[KATA]", A9), "[TYPE]", D9), "[CERF]", E9)
A10: other | B10: lainnya | C10: /ˈəðər/ | D10: ADJ | E10: A2 | F10: 46 | G10: =SUBSTITUTE(SUBSTITUTE(SUBSTITUTE(ai!$A$2, "[KATA]", A10), "[TYPE]", D10), "[CERF]", E10)
A11: no | B11: TIDAK | C11: /noʊ/ | D11: ADJ, ADV, NOUN | E11: A1 | F11: 48 | G11: =SUBSTITUTE(SUBSTITUTE(SUBSTITUTE(ai!$A$2, "[KATA]", A11), "[TYPE]", D11), "[CERF]", E11)
A12: no one | B12: tidak seorang pun | C12: /noʊ wən/ | D12: ADJ, ADV, NOUN | E12: A1 | F12: 48 | G12: =SUBSTITUTE(SUBSTITUTE(SUBSTITUTE(ai!$A$2, "[KATA]", A12), "[TYPE]", D12), "[CERF]", E12)
A13: information | B13: informasi | C13: /ˌɪnˌfɔrˈmeɪʃən/ | D13: NOUN | E13: A1 | F13: 49 | G13: =SUBSTITUTE(SUBSTITUTE(SUBSTITUTE(ai!$A$2, "[KATA]", A13), "[TYPE]", D13), "[CERF]", E13)
... A2305: miscellaneous | B2305: aneka ragam | C2305: /ˌmɪsəˈleɪniəs/ | D2305: ADJ | E2305: - | F2305: 2446 | G2305: =SUBSTITUTE(SUBSTITUTE(SUBSTITUTE(ai!$A$2, "[KATA]", A2305), "[TYPE]", D2305), "[CERF]", E2305)
B2306: batal | C2306: /nəl/ | D2306: ADJ, NOUN | E2306: - | F2306: 2446 | G2306: =SUBSTITUTE(SUBSTITUTE(SUBSTITUTE(ai!$A$2, "[KATA]", A2306), "[TYPE]", D2306), "[CERF]", E2306)
A2307: prepared | B2307: siap | C2307: /priˈpɛrd/ | D2307: ADJ, VERB | E2307: B1 | F2307: 2447 | G2307: =SUBSTITUTE(SUBSTITUTE(SUBSTITUTE(ai!$A$2, "[KATA]", A2307), "[TYPE]", D2307), "[CERF]", E2307)
A2308: void | B2308: ruang kosong | C2308: /vɔɪd/ | D2308: ADJ, NOUN, VERB | E2308: - | F2308: 2448 | G2308: =SUBSTITUTE(SUBSTITUTE(SUBSTITUTE(ai!$A$2, "[KATA]", A2308), "[TYPE]", D2308), "[CERF]", E2308)
A2309: dining | B2309: makan | C2309: /ˈdaɪnɪŋ/ | D2309: NOUN, VERB | E2309: - | F2309: 2449 | G2309: =SUBSTITUTE(SUBSTITUTE(SUBSTITUTE(ai!$A$2, "[KATA]", A2309), "[TYPE]", D2309), "[CERF]", E2309)
A2310: dining room | B2310: ruang makan | C2310: /ˈdaɪnɪŋ rum/ | D2310: NOUN, VERB | E2310: - | F2310: 2449 | G2310: =SUBSTITUTE(SUBSTITUTE(SUBSTITUTE(ai!$A$2, "[KATA]", A2310), "[TYPE]", D2310), "[CERF]", E2310)
A2311: alert | B2311: peringatan | C2311: /əˈlərt/ | D2311: ADJ, NOUN, VERB | E2311: B2 | F2311: 2450 | G2311: =SUBSTITUTE(SUBSTITUTE(SUBSTITUTE(ai!$A$2, "[KATA]", A2311), "[TYPE]", D2311), "[CERF]", E2311)
A2312: integration | B2312: integrasi | C2312: /ˌɪnəˈgreɪʃən/ | D2312: NOUN | E2312: C2 | F2312: 2451 | G2312: =SUBSTITUTE(SUBSTITUTE(SUBSTITUTE(ai!$A$2, "[KATA]", A2312), "[TYPE]", D2312), "[CERF]", E2312)
A2313: atlanta | B2313: atlanta | C2313: /æˈtlæntə/ | D2313: NOUN | E2313: - | F2313: 2452 | G2313: =SUBSTITUTE(SUBSTITUTE(SUBSTITUTE(ai!$A$2, "[KATA]", A2313), "[TYPE]", D2313), "[CERF]", E2313)
A2314: dakota | B2314: dakota | C2314: /dəˈkoʊtə/ | D2314: NOUN | E2314: - | F2314: 2453 | G2314: =SUBSTITUTE(SUBSTITUTE(SUBSTITUTE(ai!$A$2, "[KATA]", A2314), "[TYPE]", D2314), "[CERF]", E2314)
A2315: tag | B2315: menandai | C2315: /tæg/ | D2315: NOUN, VERB | E2315: B2 | F2315: 2454 | G2315: =SUBSTITUTE(SUBSTITUTE(SUBSTITUTE(ai!$A$2, "[KATA]", A2315), "[TYPE]", D2315), "[CERF]", E2315)
A2316: interview | B2316: wawancara | C2316: /ˈɪntərvˌju/ | D2316: NOUN, VERB | E2316: B1 | F2316: 2455 | G2316: =SUBSTITUTE(SUBSTITUTE(SUBSTITUTE(ai!$A$2, "[KATA]", A2316), "[TYPE]", D2316), "[CERF]", E2316)
A2317: mix | B2317: mencampur | C2317: /mɪks/ | D2317: NOUN, VERB | E2317: A2 | F2317: 2456 | G2317: =SUBSTITUTE(SUBSTITUTE(SUBSTITUTE(ai!$A$2, "[KATA]", A2317), "[TYPE]", D2317), "[CERF]", E2317)
A2318: framework | B2318: kerangka | C2318: /ˈfreɪmˌwərk/ | D2318: NOUN | E2318: - | F2318: 2457 | G2318: =SUBSTITUTE(SUBSTITUTE(SUBSTITUTE(ai!$A$2, "[KATA]", A2318), "[TYPE]", D2318), "[CERF]", E2318)
... A9513: poison | B9513: racun | C9513: /ˈpɔɪzən/ | D9513: NOUN, VERB | E9513: B2 | F9513: 10000 | G9513: =SUBSTITUTE(SUBSTITUTE(SUBSTITUTE(ai!$A$2, "[KATA]", A9513), "[TYPE]", D9513), "[CERF]", E9513)
A9514: jeopardize/jeopardise | B9514: membahayakan/membahayakan | C9514: /ˈʤɛpərˌdaɪz/ | D9514: VERB | E9514: B2 | F9514: - | G9514: =SUBSTITUTE(SUBSTITUTE(SUBSTITUTE(ai!$A$2, "[KATA]", A9514), "[TYPE]", D9514), "[CERF]", E9514)
A9515: appall/appal | B9515: mengerikan/mengejutkan | C9515: /əˈpɔl/ | D9515: VERB | E9515: C1 | F9515: - | G9515: =SUBSTITUTE(SUBSTITUTE(SUBSTITUTE(ai!$A$2, "[KATA]", A9515), "[TYPE]", D9515), "[CERF]", E9515)
A9516: sitting room | B9516: ruang duduk | C9516: /ˈsɪtɪŋ/ | D9516: ADJ, NOUN, VERB | E9516: A2 | F9516: - | G9516: =SUBSTITUTE(SUBSTITUTE(SUBSTITUTE(ai!$A$2, "[KATA]", A9516), "[TYPE]", D9516), "[CERF]", E9516)
A9517: organization/organisation | B9517: organisasi/organisasi | C9517: /ˌɔrgənəˈzeɪʃən/ | D9517: NOUN | E9517: B1 | F9517: - | G9517: =SUBSTITUTE(SUBSTITUTE(SUBSTITUTE(ai!$A$2, "[KATA]", A9517), "[TYPE]", D9517), "[CERF]", E9517)
A9518: check-in desk/check-in | B9518: meja check-in/check-in | C9518: /check-in/ | D9518: NOUN | E9518: B1 | F9518: - | G9518: =SUBSTITUTE(SUBSTITUTE(SUBSTITUTE(ai!$A$2, "[KATA]", A9518), "[TYPE]", D9518), "[CERF]", E9518)
A9519: extreme sports | B9519: olahraga ekstrim | C9519: /ɪkˈstrim/ | D9519: ADJ, NOUN | E9519: B1 | F9519: - | G9519: =SUBSTITUTE(SUBSTITUTE(SUBSTITUTE(ai!$A$2, "[KATA]", A9519), "[TYPE]", D9519), "[CERF]", E9519)
A9520: apologize/apologise | B9520: meminta maaf/meminta maaf | C9520: /əˈpɑləˌʤaɪz/ | D9520: VERB | E9520: A2 | F9520: - | G9520: =SUBSTITUTE(SUBSTITUTE(SUBSTITUTE(ai!$A$2, "[KATA]", A9520), "[TYPE]", D9520), "[CERF]", E9520)
A9521: archaeologist/archeologist | B9521: arkeolog/arkeolog | C9521: /ˌɑrkiˈɑləʤɪst/ | D9521: NOUN | E9521: B2 | F9521: - | G9521: =SUBSTITUTE(SUBSTITUTE(SUBSTITUTE(ai!$A$2, "[KATA]", A9521), "[TYPE]", D9521), "[CERF]", E9521)
A9522: chili/chilli | B9522: cabai/cabai | C9522: /ˈʧɪli/ | D9522: NOUN | E9522: A2 | F9522: - | G9522: =SUBSTITUTE(SUBSTITUTE(SUBSTITUTE(ai!$A$2, "[KATA]", A9522), "[TYPE]", D9522), "[CERF]", E9522)
A9523: somberly/sombrely | B9523: dengan sedih/suram | C9523: /ˈsɑmbərli/ | D9523: ADV | E9523: C1 | F9523: - | G9523: =SUBSTITUTE(SUBSTITUTE(SUBSTITUTE(ai!$A$2, "[KATA]", A9523), "[TYPE]", D9523), "[CERF]", E9523)
A9524: high-tech/hi-tech | B9524: teknologi tinggi/teknologi tinggi | C9524: /ˌhaɪˈtɛk/ | D9524: ADJ | E9524: B2 | F9524: - | G9524: =SUBSTITUTE(SUBSTITUTE(SUBSTITUTE(ai!$A$2, "[KATA]", A9524), "[TYPE]", D9524), "[CERF]", E9524)
A9525: laud | B9525: memuji | C9525: /lɔd/ | D9525: VERB | E9525: C2 | F9525: - | G9525: =SUBSTITUTE(SUBSTITUTE(SUBSTITUTE(ai!$A$2, "[KATA]", A9525), "[TYPE]", D9525), "[CERF]", E9525)
...

Sheet Grammar (Original)
A1: kata | B1: arti | C1: ipa | D1: type | E1: cerf | F1: top | G1: Copy Prompt
A2: the | B2: itu | C2: /ðə/ | D2: GRAMMAR (DET) | E2: A1 | F2: 1 | G2: =SUBSTITUTE(SUBSTITUTE(SUBSTITUTE(ai!$A$2, "[KATA]", A2), "[TYPE]", D2), "[CERF]", E2)
A3: of | B3: dari | C3: /əv/ | D3: GRAMMAR (ADP) | E3: A1 | F3: 2 | G3: =SUBSTITUTE(SUBSTITUTE(SUBSTITUTE(ai!$A$2, "[KATA]", A3), "[TYPE]", D3), "[CERF]", E3)
A4: and | B4: Dan | C4: /ənd/ | D4: GRAMMAR (CCONJ) | E4: A1 | F4: 3 | G4: =SUBSTITUTE(SUBSTITUTE(SUBSTITUTE(ai!$A$2, "[KATA]", A4), "[TYPE]", D4), "[CERF]", E4)
A5: to | B5: ke | C5: /tɪ/ | D5: GRAMMAR (PART) | E5: A1 | F5: 4 | G5: =SUBSTITUTE(SUBSTITUTE(SUBSTITUTE(ai!$A$2, "[KATA]", A5), "[TYPE]", D5), "[CERF]", E5)
A6: a | B6: A | C6: /ə/ | D6: GRAMMAR (DET) | E6: A1 | F6: 5 | G6: =SUBSTITUTE(SUBSTITUTE(SUBSTITUTE(ai!$A$2, "[KATA]", A6), "[TYPE]", D6), "[CERF]", E6)
A7: in | B7: di dalam | C7: /ɪn/ | D7: GRAMMAR (ADP) | E7: A1 | F7: 6 | G7: =SUBSTITUTE(SUBSTITUTE(SUBSTITUTE(ai!$A$2, "[KATA]", A7), "[TYPE]", D7), "[CERF]", E7)
A8: for | B8: untuk | C8: /fər/ | D8: GRAMMAR (ADP) | E8: A1 | F8: 7 | G8: =SUBSTITUTE(SUBSTITUTE(SUBSTITUTE(ai!$A$2, "[KATA]", A8), "[TYPE]", D8), "[CERF]", E8)
A9: is | B9: adalah | C9: /ɪz/ | D9: GRAMMAR (AUX) | E9: A1 | F9: 8 | G9: =SUBSTITUTE(SUBSTITUTE(SUBSTITUTE(ai!$A$2, "[KATA]", A9), "[TYPE]", D9), "[CERF]", E9)
A10: on | B10: pada | C10: /ɔn/ | D10: GRAMMAR (ADP) | E10: A1 | F10: 9 | G10: =SUBSTITUTE(SUBSTITUTE(SUBSTITUTE(ai!$A$2, "[KATA]", A10), "[TYPE]", D10), "[CERF]", E10)
A11: that | B11: itu | C11: /ðət/ | D11: GRAMMAR (SCONJ) | E11: A1 | F11: 10 | G11: =SUBSTITUTE(SUBSTITUTE(SUBSTITUTE(ai!$A$2, "[KATA]", A11), "[TYPE]", D11), "[CERF]", E11)
A12: by | B12: oleh | C12: /baɪ/ | D12: GRAMMAR (ADP) | E12: A1 | F12: 11 | G12: =SUBSTITUTE(SUBSTITUTE(SUBSTITUTE(ai!$A$2, "[KATA]", A12), "[TYPE]", D12), "[CERF]", E12)
A13: this | B13: ini | C13: /ðɪs/ | D13: GRAMMAR (DET) | E13: A1 | F13: 12 | G13: =SUBSTITUTE(SUBSTITUTE(SUBSTITUTE(ai!$A$2, "[KATA]", A13), "[TYPE]", D13), "[CERF]", E13)
... A153: holocaust | B153: bencana | C153: /ˈhɔləˌkɔst/ | D153: GRAMMAR (PRON) | E153: B2 | F153: 9216 | G153: =SUBSTITUTE(SUBSTITUTE(SUBSTITUTE(ai!$A$2, "[KATA]", A153), "[TYPE]", D153), "[CERF]", E153)
A154: 're | B154: 'ulang | C154: /'ri/ | D154: GRAMMAR (AUX) | E154: A1 | F154: - | G154: =SUBSTITUTE(SUBSTITUTE(SUBSTITUTE(ai!$A$2, "[KATA]", A154), "[TYPE]", D154), "[CERF]", E154)
A155: whoever | B155: siapapun | C155: /huˈɛvər/ | D155: GRAMMAR (PRON) | E155: B1 | F155: - | G155: =SUBSTITUTE(SUBSTITUTE(SUBSTITUTE(ai!$A$2, "[KATA]", A155), "[TYPE]", D155), "[CERF]", E155)
A156: up-to-date | B156: terkini | C156: /up-to-date/ | D156: GRAMMAR (ADP) | E156: B1 | F156: - | G156: =SUBSTITUTE(SUBSTITUTE(SUBSTITUTE(ai!$A$2, "[KATA]", A156), "[TYPE]", D156), "[CERF]", E156)
A157: underneath | B157: di bawah | C157: /ˌəndərˈniθ/ | D157: GRAMMAR (ADP) | E157: B1 | F157: - | G157: =SUBSTITUTE(SUBSTITUTE(SUBSTITUTE(ai!$A$2, "[KATA]", A157), "[TYPE]", D157), "[CERF]", E157)
A158: out-of-date | B158: ketinggalan jaman | C158: /out-of-date/ | D158: GRAMMAR (ADP) | E158: B1 | F158: - | G158: =SUBSTITUTE(SUBSTITUTE(SUBSTITUTE(ai!$A$2, "[KATA]", A158), "[TYPE]", D158), "[CERF]", E158)
A159: oneself | B159: diri | C159: /ˌwənˈsɛlf/ | D159: GRAMMAR (PRON) | E159: B1 | F159: - | G159: =SUBSTITUTE(SUBSTITUTE(SUBSTITUTE(ai!$A$2, "[KATA]", A159), "[TYPE]", D159), "[CERF]", E159)
A160: underneath | B160: di bawah | C160: /ˌəndərˈniθ/ | D160: GRAMMAR (ADP) | E160: B1 | F160: - | G160: =SUBSTITUTE(SUBSTITUTE(SUBSTITUTE(ai!$A$2, "[KATA]", A160), "[TYPE]", D160), "[CERF]", E160)
A161: bookshelf | B161: rak buku | C161: /ˈbʊkˌʃɛlf/ | D161: GRAMMAR (PRON) | E161: A2 | F161: - | G161: =SUBSTITUTE(SUBSTITUTE(SUBSTITUTE(ai!$A$2, "[KATA]", A161), "[TYPE]", D161), "[CERF]", E161)
A162: whichever | B162: manapun | C162: /wɪˈʧɛvər/ | D162: GRAMMAR (DET) | E162: B2 | F162: - | G162: =SUBSTITUTE(SUBSTITUTE(SUBSTITUTE(ai!$A$2, "[KATA]", A162), "[TYPE]", D162), "[CERF]", E162)
A163: stepfather | B163: ayah tiri | C163: /ˈstɛpˌfɑðər/ | D163: GRAMMAR (ADP) | E163: B2 | F163: - | G163: =SUBSTITUTE(SUBSTITUTE(SUBSTITUTE(ai!$A$2, "[KATA]", A163), "[TYPE]", D163), "[CERF]", E163)
A164: whichever | B164: manapun | C164: /wɪˈʧɛvər/ | D164: GRAMMAR (DET) | E164: B2 | F164: - | G164: =SUBSTITUTE(SUBSTITUTE(SUBSTITUTE(ai!$A$2, "[KATA]", A164), "[TYPE]", D164), "[CERF]", E164)
A165: aboard | B165: di atas kapal | C165: /əˈbɔrd/ | D165: GRAMMAR (ADP) | E165: C1 | F165: - | G165: =SUBSTITUTE(SUBSTITUTE(SUBSTITUTE(ai!$A$2, "[KATA]", A165), "[TYPE]", D165), "[CERF]", E165)
... A173: each other | B173: satu sama lain | C173: /iʧ/ | D173: GRAMMAR (DET) | E173: A1 | F173: - | G173: =SUBSTITUTE(SUBSTITUTE(SUBSTITUTE(ai!$A$2, "[KATA]", A173), "[TYPE]", D173), "[CERF]", E173)

Sheet Main (Wuthuring)
A1: kata | B1: arti | C1: ipa | D1: type | E1: cerf | F1: top | G1: total | H1: Copy Prompt
A2: talk | B2: bicara | C2: /tɔk/ | D2: NOUN, VERB | E2: A1 | F2: 816 | G2: 3366 | H2: =SUBSTITUTE(SUBSTITUTE(SUBSTITUTE(ai!$A$2, "[KATA]", A2), "[TYPE]", D2), "[CERF]", E2)
A3: dialogue | B3: dialog | C3: /ˈdaɪəˌlɔg/ | D3: NOUN | E3: - | F3: 5495 | G3: 3311 | H3: =SUBSTITUTE(SUBSTITUTE(SUBSTITUTE(ai!$A$2, "[KATA]", A3), "[TYPE]", D3), "[CERF]", E3)
A4: icon | B4: ikon | C4: /ˈaɪkɑn/ | D4: NOUN | E4: B2 | F4: 2368 | G4: 3276 | H4: =SUBSTITUTE(SUBSTITUTE(SUBSTITUTE(ai!$A$2, "[KATA]", A4), "[TYPE]", D4), "[CERF]", E4)
A5: rover | B5: bajak | C5: /ˈroʊvər/ | D5: NOUN | E5: - | F5: 6965 | G5: 2614 | H5: =SUBSTITUTE(SUBSTITUTE(SUBSTITUTE(ai!$A$2, "[KATA]", A5), "[TYPE]", D5), "[CERF]", E5)
A6: one | B6: satu | C6: /wən/ | D6: ADJ, NOUN | E6: A2 | F6: 45 | G6: 1168 | H6: =SUBSTITUTE(SUBSTITUTE(SUBSTITUTE(ai!$A$2, "[KATA]", A6), "[TYPE]", D6), "[CERF]", E6)
A7: just | B7: hanya | C7: /ʤɪst/ | D7: ADJ, ADV | E7: A1 | F7: 109 | G7: 1124 | H7: =SUBSTITUTE(SUBSTITUTE(SUBSTITUTE(ai!$A$2, "[KATA]", A7), "[TYPE]", D7), "[CERF]", E7)
A8: so | B8: Jadi | C8: /soʊ/ | D8: ADV, NOUN | E8: A1 | F8: 66 | G8: 1115 | H8: =SUBSTITUTE(SUBSTITUTE(SUBSTITUTE(ai!$A$2, "[KATA]", A8), "[TYPE]", D8), "[CERF]", E8)
A9: here | B9: Di Sini | C9: /hir/ | D9: ADJ, ADV, NOUN | E9: A1 | F9: 70 | G9: 1102 | H9: =SUBSTITUTE(SUBSTITUTE(SUBSTITUTE(ai!$A$2, "[KATA]", A9), "[TYPE]", D9), "[CERF]", E9)
A10: now | B10: Sekarang | C10: /naʊ/ | D10: ADV, NOUN | E10: B2 | F10: 75 | G10: 1055 | H10: =SUBSTITUTE(SUBSTITUTE(SUBSTITUTE(ai!$A$2, "[KATA]", A10), "[TYPE]", D10), "[CERF]", E10)
A11: like | B11: menyukai | C11: /laɪk/ | D11: ADJ, NOUN, VERB | E11: A1 | F11: 96 | G11: 1034 | H11: =SUBSTITUTE(SUBSTITUTE(SUBSTITUTE(ai!$A$2, "[KATA]", A11), "[TYPE]", D11), "[CERF]", E11)
A12: no | B12: TIDAK | C12: /noʊ/ | D12: ADJ, ADV, NOUN | E12: A1 | F12: 48 | G12: 1033 | H12: =SUBSTITUTE(SUBSTITUTE(SUBSTITUTE(ai!$A$2, "[KATA]", A12), "[TYPE]", D12), "[CERF]", E12)
A13: re | B13: ulang | C13: /ri/ | D13: NOUN | E13: - | F13: 120 | G13: 1001 | H13: =SUBSTITUTE(SUBSTITUTE(SUBSTITUTE(ai!$A$2, "[KATA]", A13), "[TYPE]", D13), "[CERF]", E13)
... A15: about | B15: tentang | C15: /əˈbaʊt/ | D15: ADJ, ADV | E15: A1 | F15: 36 | G15: 831 | H15: =SUBSTITUTE(SUBSTITUTE(SUBSTITUTE(ai!$A$2, "[KATA]", A15), "[TYPE]", D15), "[CERF]", E15)
A16: cartethyia | B16: kartetia | C16: /cartethyia/ | D16: NOUN (Brand/Name) | E16: - | F16: - | G16: 796 | H16: =SUBSTITUTE(SUBSTITUTE(SUBSTITUTE(ai!$A$2, "[KATA]", A16), "[TYPE]", D16), "[CERF]", E16)
A17: don | B17: mengenakan | C17: /dɑn/ | D17: NOUN, VERB | E17: - | F17: 2982 | G17: 735 | H17: =SUBSTITUTE(SUBSTITUTE(SUBSTITUTE(ai!$A$2, "[KATA]", A17), "[TYPE]", D17), "[CERF]", E17)
A18: up | B18: ke atas | C18: /əp/ | D18: ADJ, ADV, VERB | E18: A1 | F18: 54 | G18: 700 | H18: =SUBSTITUTE(SUBSTITUTE(SUBSTITUTE(ai!$A$2, "[KATA]", A18), "[TYPE]", D18), "[CERF]", E18)
A19: yangyang | B19: yangyang | C19: /yangyang/ | D19: NOUN (Brand/Name) | E19: - | F19: - | G19: 697 | H19: =SUBSTITUTE(SUBSTITUTE(SUBSTITUTE(ai!$A$2, "[KATA]", A19), "[TYPE]", D19), "[CERF]", E19)
A20: let | B20: membiarkan | C20: /lɛt/ | D20: NOUN, VERB | E20: A1 | F20: 543 | G20: 689 | H20: =SUBSTITUTE(SUBSTITUTE(SUBSTITUTE(ai!$A$2, "[KATA]", A20), "[TYPE]", D20), "[CERF]", E20)
A21: out | B21: keluar | C21: /aʊt/ | D21: ADJ, ADV, NOUN, VERB | E21: A1 | F21: 60 | G21: 686 | H21: =SUBSTITUTE(SUBSTITUTE(SUBSTITUTE(ai!$A$2, "[KATA]", A21), "[TYPE]", D21), "[CERF]", E21)
A22: augusta | B22: Agustus | C22: /əˈgəstə/ | D22: NOUN | E22: - | F22: - | G22: 682 | H22: =SUBSTITUTE(SUBSTITUTE(SUBSTITUTE(ai!$A$2, "[KATA]", A22), "[TYPE]", D22), "[CERF]", E22)
A23: lynae | B23: lynae | C23: /lynae/ | D23: VERB | E23: - | F23: - | G23: 674 | H23: =SUBSTITUTE(SUBSTITUTE(SUBSTITUTE(ai!$A$2, "[KATA]", A23), "[TYPE]", D23), "[CERF]", E23)
A24: see | B24: melihat | C24: /si/ | D24: NOUN, VERB | E24: A1 | F24: 64 | G24: 648 | H24: =SUBSTITUTE(SUBSTITUTE(SUBSTITUTE(ai!$A$2, "[KATA]", A24), "[TYPE]", D24), "[CERF]", E24)
A25: chisa | B25: chisa | C25: /chisa/ | D25: NOUN (Tech/Modern) | E25: - | F25: - | G25: 626 | H25: =SUBSTITUTE(SUBSTITUTE(SUBSTITUTE(ai!$A$2, "[KATA]", A25), "[TYPE]", D25), "[CERF]", E25)
A26: more | B26: lagi | C26: /mɔr/ | D26: ADJ, ADV, NOUN | E26: A1 | F26: 28 | G26: 622 | H26: =SUBSTITUTE(SUBSTITUTE(SUBSTITUTE(ai!$A$2, "[KATA]", A26), "[TYPE]", D26), "[CERF]", E26)
A27: abby | B27: abby | C27: /ˈæbi/ | D27: NOUN (Brand/Name) | E27: - | F27: - | G27: 609 | H27: =SUBSTITUTE(SUBSTITUTE(SUBSTITUTE(ai!$A$2, "[KATA]", A27), "[TYPE]", D27), "[CERF]", E27)
A28: iuno | B28: aku tidak | C28: /iuno/ | D28: NOUN (Brand/Name) | E28: - | F28: - | G28: 607 | H28: =SUBSTITUTE(SUBSTITUTE(SUBSTITUTE(ai!$A$2, "[KATA]", A28), "[TYPE]", D28), "[CERF]", E28)
A29: know | B29: tahu | C29: /noʊ/ | D29: NOUN, VERB | E29: A1 | F29: 201 | G29: 603 | H29: =SUBSTITUTE(SUBSTITUTE(SUBSTITUTE(ai!$A$2, "[KATA]", A29), "[TYPE]", D29), "[CERF]", E29)
A30: go | B30: pergi | C30: /goʊ/ | D30: ADJ, NOUN, VERB | E30: A1 | F30: 123 | G30: 602 | H30: =SUBSTITUTE(SUBSTITUTE(SUBSTITUTE(ai!$A$2, "[KATA]", A30), "[TYPE]", D30), "[CERF]", E30)
A31: still | B31: tetap | C31: /stɪl/ | D31: ADJ, ADV, NOUN, VERB | E31: A2 | F31: 390 | G31: 593 | H31: =SUBSTITUTE(SUBSTITUTE(SUBSTITUTE(ai!$A$2, "[KATA]", A31), "[TYPE]", D31), "[CERF]", E31)
A32: dark | B32: gelap | C32: /dɑrk/ | D32: ADJ, NOUN | E32: A1 | F32: 1640 | G32: 585 | H32: =SUBSTITUTE(SUBSTITUTE(SUBSTITUTE(ai!$A$2, "[KATA]", A32), "[TYPE]", D32), "[CERF]", E32)
A33: phrolova | B33: phrolova | C33: /phrolova/ | D33: NOUN (Brand/Name) | E33: - | F33: - | G33: 582 | H33: =SUBSTITUTE(SUBSTITUTE(SUBSTITUTE(ai!$A$2, "[KATA]", A33), "[TYPE]", D33), "[CERF]", E33)
A34: only | B34: hanya | C34: /ˈoʊnli/ | D34: ADJ, ADV | E34: A1 | F34: 65 | G34: 576 | H34: =SUBSTITUTE(SUBSTITUTE(SUBSTITUTE(ai!$A$2, "[KATA]", A34), "[TYPE]", D34), "[CERF]", E34)
A35: lupa | B35: lupa | C35: /ˈlupə/ | D35: ADJ | E35: - | F35: - | G35: 562 | H35: =SUBSTITUTE(SUBSTITUTE(SUBSTITUTE(ai!$A$2, "[KATA]", A35), "[TYPE]", D35), "[CERF]", E35)
A36: tide | B36: gelombang pasang | C36: /taɪd/ | D36: NOUN, VERB | E36: B1 | F36: 8252 | G36: 562 | H36: =SUBSTITUTE(SUBSTITUTE(SUBSTITUTE(ai!$A$2, "[KATA]", A36), "[TYPE]", D36), "[CERF]", E36)
A37: mornye | B37: pagi hari | C37: /mornye/ | D37: NOUN (Brand/Name) | E37: - | F37: - | G37: 555 | H37: =SUBSTITUTE(SUBSTITUTE(SUBSTITUTE(ai!$A$2, "[KATA]", A37), "[TYPE]", D37), "[CERF]", E37)
A38: sentinel | B38: penjaga | C38: /ˈsɛntənəl/ | D38: NOUN | E38: - | F38: - | G38: 553 | H38: =SUBSTITUTE(SUBSTITUTE(SUBSTITUTE(ai!$A$2, "[KATA]", A38), "[TYPE]", D38), "[CERF]", E38)
A39: need | B39: membutuhkan | C39: /nid/ | D39: NOUN, VERB | E39: A2 | F39: 183 | G39: 534 | H39: =SUBSTITUTE(SUBSTITUTE(SUBSTITUTE(ai!$A$2, "[KATA]", A39), "[TYPE]", D39), "[CERF]", E39)
A40: carlotta | B40: carlotta | C40: /kɑˈrlɔtɑ/ | D40: NOUN (Brand/Name) | E40: - | F40: - | G40: 525 | H40: =SUBSTITUTE(SUBSTITUTE(SUBSTITUTE(ai!$A$2, "[KATA]", A40), "[TYPE]", D40), "[CERF]", E40)
A41: shorekeeper | B41: penjaga pantai | C41: /shorekeeper/ | D41: NOUN (Tech/Modern) | E41: - | F41: - | G41: 516 | H41: =SUBSTITUTE(SUBSTITUTE(SUBSTITUTE(ai!$A$2, "[KATA]", A41), "[TYPE]", D41), "[CERF]", E41)
...

Sheet Grammar (Wuthuring)
A1: kata | B1: arti | C1: ipa | D1: type | E1: cerf | F1: top | G1: total | H1: Copy Prompt
A2: the | B2: itu | C2: /ðə/ | D2: GRAMMAR (DET) | E2: A1 | F2: 1 | G2: 18092 | H2: =SUBSTITUTE(SUBSTITUTE(SUBSTITUTE(ai!$A$2, "[KATA]", A2), "[TYPE]", D2), "[CERF]", E2)
A3: to | B3: ke | C3: /tɪ/ | D3: GRAMMAR (PART) | E3: A1 | F3: 4 | G3: 8491 | H3: =SUBSTITUTE(SUBSTITUTE(SUBSTITUTE(ai!$A$2, "[KATA]", A3), "[TYPE]", D3), "[CERF]", E3)
A4: you | B4: Anda | C4: /ju/ | D4: GRAMMAR (PRON) | E4: A1 | F4: 15 | G4: 7712 | H4: =SUBSTITUTE(SUBSTITUTE(SUBSTITUTE(ai!$A$2, "[KATA]", A4), "[TYPE]", D4), "[CERF]", E4)
A5: i | B5: Saya | C5: /aɪ/ | D5: GRAMMAR (PRON) | E5: A1 | F5: 14 | G5: 7485 | H5: =SUBSTITUTE(SUBSTITUTE(SUBSTITUTE(ai!$A$2, "[KATA]", A5), "[TYPE]", D5), "[CERF]", E5)
A6: a | B6: A | C6: /ə/ | D6: GRAMMAR (DET) | E6: A1 | F6: 5 | G6: 5269 | H6: =SUBSTITUTE(SUBSTITUTE(SUBSTITUTE(ai!$A$2, "[KATA]", A6), "[TYPE]", D6), "[CERF]", E6)
A7: it | B7: dia | C7: /ɪt/ | D7: GRAMMAR (PRON) | E7: A1 | F7: 16 | G7: 5185 | H7: =SUBSTITUTE(SUBSTITUTE(SUBSTITUTE(ai!$A$2, "[KATA]", A7), "[TYPE]", D7), "[CERF]", E7)
A8: of | B8: dari | C8: /əv/ | D8: GRAMMAR (ADP) | E8: A1 | F8: 2 | G8: 4970 | H8: =SUBSTITUTE(SUBSTITUTE(SUBSTITUTE(ai!$A$2, "[KATA]", A8), "[TYPE]", D8), "[CERF]", E8)
A9: and | B9: Dan | C9: /ənd/ | D9: GRAMMAR (CCONJ) | E9: A1 | F9: 3 | G9: 4158 | H9: =SUBSTITUTE(SUBSTITUTE(SUBSTITUTE(ai!$A$2, "[KATA]", A9), "[TYPE]", D9), "[CERF]", E9)
A10: that | B10: itu | C10: /ðət/ | D10: GRAMMAR (SCONJ) | E10: A1 | F10: 10 | G10: 3278 | H10: =SUBSTITUTE(SUBSTITUTE(SUBSTITUTE(ai!$A$2, "[KATA]", A10), "[TYPE]", D10), "[CERF]", E10)
A11: is | B11: adalah | C11: /ɪz/ | D11: GRAMMAR (AUX) | E11: A1 | F11: 8 | G11: 3229 | H11: =SUBSTITUTE(SUBSTITUTE(SUBSTITUTE(ai!$A$2, "[KATA]", A11), "[TYPE]", D11), "[CERF]", E11)
A12: in | B12: di dalam | C12: /ɪn/ | D12: GRAMMAR (ADP) | E12: A1 | F12: 6 | G12: 3173 | H12: =SUBSTITUTE(SUBSTITUTE(SUBSTITUTE(ai!$A$2, "[KATA]", A12), "[TYPE]", D12), "[CERF]", E12)
A13: we | B13: Kami | C13: /wi/ | D13: GRAMMAR (PRON) | E13: A1 | F13: 31 | G13: 2793 | H13: =SUBSTITUTE(SUBSTITUTE(SUBSTITUTE(ai!$A$2, "[KATA]", A13), "[TYPE]", D13), "[CERF]", E13)
... A103: both | B103: keduanya | C103: /boʊθ/ | D103: GRAMMAR (DET) | E103: A1 | F103: 300 | G103: 115 | H103: =SUBSTITUTE(SUBSTITUTE(SUBSTITUTE(ai!$A$2, "[KATA]", A103), "[TYPE]", D103), "[CERF]", E103)
A104: cannot | B104: tidak bisa | C104: /ˈkænɑt/ | D104: GRAMMAR (AUX) | E104: - | F104: - | G104: 112 | H104: =SUBSTITUTE(SUBSTITUTE(SUBSTITUTE(ai!$A$2, "[KATA]", A104), "[TYPE]", D104), "[CERF]", E104)
A105: upon | B105: pada | C105: /əˈpɑn/ | D105: GRAMMAR (SCONJ) | E105: A2 | F105: 765 | G105: 102 | H105: =SUBSTITUTE(SUBSTITUTE(SUBSTITUTE(ai!$A$2, "[KATA]", A105), "[TYPE]", D105), "[CERF]", E105)
A106: itself | B106: diri | C106: /ˌɪtˈsɛlf/ | D106: GRAMMAR (PRON) | E106: A2 | F106: 1625 | G106: 95 | H106: =SUBSTITUTE(SUBSTITUTE(SUBSTITUTE(ai!$A$2, "[KATA]", A106), "[TYPE]", D106), "[CERF]", E106)
A107: each | B107: setiap | C107: /iʧ/ | D107: GRAMMAR (DET) | E107: A1 | F107: 168 | G107: 93 | H107: =SUBSTITUTE(SUBSTITUTE(SUBSTITUTE(ai!$A$2, "[KATA]", A107), "[TYPE]", D107), "[CERF]", E107)
A108: which | B108: yang | C108: /wɪʧ/ | D108: GRAMMAR (Question Word) | E108: A1 | F108: 57 | G108: 86 | H108: =SUBSTITUTE(SUBSTITUTE(SUBSTITUTE(ai!$A$2, "[KATA]", A108), "[TYPE]", D108), "[CERF]", E108)
A109: along | B109: bersama | C109: /əˈlɔŋ/ | D109: GRAMMAR (ADP) | E109: A2 | F109: 965 | G109: 81 | H109: =SUBSTITUTE(SUBSTITUTE(SUBSTITUTE(ai!$A$2, "[KATA]", A109), "[TYPE]", D109), "[CERF]", E109)
A110: across | B110: lintas | C110: /əˈkrɔs/ | D110: GRAMMAR (ADP) | E110: A2 | F110: 1057 | G110: 75 | H110: =SUBSTITUTE(SUBSTITUTE(SUBSTITUTE(ai!$A$2, "[KATA]", A110), "[TYPE]", D110), "[CERF]", E110)
A111: anyone | B111: siapa pun | C111: /ˈɛniˌwən/ | D111: GRAMMAR (PRON) | E111: A1 | F111: 1084 | G111: 72 | H111: =SUBSTITUTE(SUBSTITUTE(SUBSTITUTE(ai!$A$2, "[KATA]", A111), "[TYPE]", D111), "[CERF]", E111)
A112: beneath | B112: di bawah | C112: /bɪˈniθ/ | D112: GRAMMAR (ADP) | E112: B1 | F112: 7737 | G112: 66 | H112: =SUBSTITUTE(SUBSTITUTE(SUBSTITUTE(ai!$A$2, "[KATA]", A112), "[TYPE]", D112), "[CERF]", E112)
A113: whatever | B113: apa pun | C113: /ˌwəˈtɛvər/ | D113: GRAMMAR (DET) | E113: B1 | F113: 2501 | G113: 65 | H113: =SUBSTITUTE(SUBSTITUTE(SUBSTITUTE(ai!$A$2, "[KATA]", A113), "[TYPE]", D113), "[CERF]", E113)
A114: near | B114: di dekat | C114: /nɪr/ | D114: GRAMMAR (ADP) | E114: A1 | F114: 989 | G114: 56 | H114: =SUBSTITUTE(SUBSTITUTE(SUBSTITUTE(ai!$A$2, "[KATA]", A114), "[TYPE]", D114), "[CERF]", E114)
A115: herself | B115: diri | C115: /hərˈsɛlf/ | D115: GRAMMAR (PRON) | E115: A2 | F115: 4946 | G115: 53 | H115: =SUBSTITUTE(SUBSTITUTE(SUBSTITUTE(ai!$A$2, "[KATA]", A115), "[TYPE]", D115), "[CERF]", E115)
A116: whether | B116: apakah | C116: /ˈwɛðər/ | D116: GRAMMAR (SCONJ) | E116: B1 | F116: 760 | G116: 38 | H116: =SUBSTITUTE(SUBSTITUTE(SUBSTITUTE(ai!$A$2, "[KATA]", A116), "[TYPE]", D116), "[CERF]", E116)
... A121: neither | B121: juga tidak | C121: /ˈniðər/ | D121: GRAMMAR (CCONJ) | E121: B2 | F121: 3360 | G121: 24 | H121: =SUBSTITUTE(SUBSTITUTE(SUBSTITUTE(ai!$A$2, "[KATA]", A121), "[TYPE]", D121), "[CERF]", E121)
A122: murmurstown | B122: kota bergumam | C122: /murmurstown/ | D122: GRAMMAR (ADP) | E122: - | F122: - | G122: 24 | H122: =SUBSTITUTE(SUBSTITUTE(SUBSTITUTE(ai!$A$2, "[KATA]", A122), "[TYPE]", D122), "[CERF]", E122)
A123: themselves | B123: diri | C123: /ðɛmˈsɛlvz/ | D123: GRAMMAR (PRON) | E123: A2 | F123: 1745 | G123: 23 | H123: =SUBSTITUTE(SUBSTITUTE(SUBSTITUTE(ai!$A$2, "[KATA]", A123), "[TYPE]", D123), "[CERF]", E123)
A124: unless | B124: kecuali | C124: /ənˈlɛs/ | D124: GRAMMAR (SCONJ) | E124: B1 | F124: 1577 | G124: 22 | H124: =SUBSTITUTE(SUBSTITUTE(SUBSTITUTE(ai!$A$2, "[KATA]", A124), "[TYPE]", D124), "[CERF]", E124)
A125: plus | B125: plus | C125: /pləs/ | D125: GRAMMAR (CCONJ) | E125: A2 | F125: 844 | G125: 20 | H125: =SUBSTITUTE(SUBSTITUTE(SUBSTITUTE(ai!$A$2, "[KATA]", A125), "[TYPE]", D125), "[CERF]", E125)
A126: himself | B126: diri | C126: /hɪmˈsɛlf/ | D126: GRAMMAR (PRON) | E126: A2 | F126: 2038 | G126: 18 | H126: =SUBSTITUTE(SUBSTITUTE(SUBSTITUTE(ai!$A$2, "[KATA]", A126), "[TYPE]", D126), "[CERF]", E126)
A127: id | B127: pengenal | C127: /ˈaɪˈdi/ | D127: GRAMMAR (PRON) | E127: A2 | F127: 654 | G127: 17 | H127: =SUBSTITUTE(SUBSTITUTE(SUBSTITUTE(ai!$A$2, "[KATA]", A127), "[TYPE]", D127), "[CERF]", E127)
A128: till | B128: sampai | C128: /tɪl/ | D128: GRAMMAR (SCONJ) | E128: C1 | F128: 4267 | G128: 17 | H128: =SUBSTITUTE(SUBSTITUTE(SUBSTITUTE(ai!$A$2, "[KATA]", A128), "[TYPE]", D128), "[CERF]", E128)
A129: wherever | B129: di manapun | C129: /wɛˈrɛvər/ | D129: GRAMMAR (SCONJ) | E129: B1 | F129: 8209 | G129: 16 | H129: =SUBSTITUTE(SUBSTITUTE(SUBSTITUTE(ai!$A$2, "[KATA]", A129), "[TYPE]", D129), "[CERF]", E129)
A130: amidst | B130: di tengah-tengah | C130: /əˈmɪdst/ | D130: GRAMMAR (ADP) | E130: - | F130: - | G130: 16 | H130: =SUBSTITUTE(SUBSTITUTE(SUBSTITUTE(ai!$A$2, "[KATA]", A130), "[TYPE]", D130), "[CERF]", E130)
A131: whenever | B131: kapan pun | C131: /wɛˈnɛvər/ | D131: GRAMMAR (SCONJ) | E131: B1 | F131: 4745 | G131: 16 | H131: =SUBSTITUTE(SUBSTITUTE(SUBSTITUTE(ai!$A$2, "[KATA]", A131), "[TYPE]", D131), "[CERF]", E131)
A132: whose | B132: yang | C132: /huz/ | D132: GRAMMAR (Question Word) | E132: A1 | F132: 1881 | G132: 14 | H132: =SUBSTITUTE(SUBSTITUTE(SUBSTITUTE(ai!$A$2, "[KATA]", A132), "[TYPE]", D132), "[CERF]", E132)
A133: thessaleo | B133: tessaleo | C133: /thessaleo/ | D133: GRAMMAR (DET) | E133: - | F133: - | G133: 12 | H133: =SUBSTITUTE(SUBSTITUTE(SUBSTITUTE(ai!$A$2, "[KATA]", A133), "[TYPE]", D133), "[CERF]", E133)
...

Sheet ai
A1: Prompt Template
A2: Di sini saya ingin belajar kosakata bahasa Inggris: - [KATA] (kelas kata: [TYPE], target level Cerf: [CERF]) Tugasmu: 1. Untuk kata tersebut, buatlah 5 contoh dialog di mana dialog itu menghasilkan 2 kalimat saja (yang dimana kalimat sehari-hari) dan boleh ada kata kerja v1, v2, v3, v-ing. 2. Pastikan tingkat kesulitan kosakata tambahan dan gaya bahasa dalam dialog disesuaikan dengan level Target Cerf agar pas dengan kemampuan saya. 3. Cantumkan keterangan kelas kata di samping kata tersebut. 4. Di bawahnya jika kamu sudah bikin kalimatnya tambahin internasional phonetic alfabet (IPA) dari kalimat yang kamu bikin. 5. Tambahin bahasa translate ke indonesia di bawah IPA. 6. Susun balasan dengan format: strukturnya : # [KATA] ([TYPE] - Level Cerf Target Saya) ## Dialog 1 A: … B: … (IPA) (ARTI) ## Dialog 2 A: … B: … (IPA) (ARTI) (Lanjutkan sampai Dialog 5) --- Contoh hasil: # area (noun - Level A1 atau B2) ## Dialog 1 A: This area of the park is always shaded. B: It’s perfect for a picnic. (IPA) /ðɪs ˈɛəriə əv ðə pɑːrk ɪz ˈɔːlweɪz ˈʃeɪdɪd/ /ɪts ˈpɜːrfɪkt fɔːr ə ˈpɪknɪk/ (ARTI) Area taman ini selalu teduh. Cocok untuk piknik.
